<?xml version="1.0" ?>
<!-- =================================================================================== -->
<!-- |    This document was autogenerated by xacro from kaqi.urdf.xacro                | -->
<!-- |    EDITING THIS FILE BY HAND IS NOT RECOMMENDED                                 | -->
<!-- =================================================================================== -->
<robot name="kaqi" xmlns:controller="http://playerstage.sourceforge.net/gazebo/xmlschema/#controller" xmlns:interface="http://playerstage.sourceforge.net/gazebo/xmlschema/#interface" xmlns:sensor="http://playerstage.sourceforge.net/gazebo/xmlschema/#sensor" xmlns:xacro="http://ros.org/wiki/xacro">
  <!-- 0.016 -->
  <!-- 0.0 -->
  <material name="black">
    <color rgba="0.0 0.0 0.0 1.0"/>
  </material>
  <material name="blue">
    <color rgba="0.0 0.0 0.8 1.0"/>
  </material>
  <material name="green">
    <color rgba="0.0 0.8 0.0 1.0"/>
  </material>
  <material name="grey">
    <color rgba="0.2 0.2 0.2 1.0"/>
  </material>
  <material name="turquoise">
    <color rgba="0.0 0.8 0.8 1.0"/>
  </material>
  <material name="orange">
    <color rgba="1.0 0.423529411765 0.0392156862745 1.0"/>
  </material>
  <material name="brown">
    <color rgba="0.870588235294 0.811764705882 0.764705882353 1.0"/>
  </material>
  <material name="red">
    <color rgba="0.8 0.0 0.0 1.0"/>
  </material>
  <material name="white">
    <color rgba="1.0 1.0 1.0 1.0"/>
  </material>
  <!-- 0.016 -->
  <!-- 0.0 -->
  <gazebo>
    <plugin filename="libgazebo_ros_imu.so" name="imu_controller">
      <alwaysOn>true</alwaysOn>
      <updateRate>100</updateRate>
      <bodyName>imu_link</bodyName>
      <topicName>imu/data</topicName>
      <gaussianNoise>2.89e-08</gaussianNoise>
      <xyzOffset>0 0 0</xyzOffset>
      <rpyOffset>0 -180.0 0</rpyOffset>
      <serviceName>/default_imu</serviceName>
    </plugin>
  </gazebo>
  <gazebo reference="left_wheel_link">
    <mu1 value="100.0"/>
    <mu2 value="100.0"/>
    <kp value="1000000.0"/>
    <kd value="1.0"/>
    <maxVel value="100.0"/>
    <minDepth value="0.0"/>
    <material>Gazebo/Black</material>
  </gazebo>
  <gazebo reference="right_wheel_link">
    <mu1 value="100.0"/>
    <mu2 value="100.0"/>
    <kp value="1000000.0"/>
    <kd value="1.0"/>
    <maxVel value="100.0"/>
    <minDepth value="0.0"/>
    <material>Gazebo/Black</material>
  </gazebo>
  <gazebo reference="caster_rotate_link">
    <mu1>0.0</mu1>
    <mu2>0.0</mu2>
    <material>Gazebo/Grey</material>
  </gazebo>
  <gazebo reference="caster_wheel_link">
    <mu1>100.0</mu1>
    <mu2>100.0</mu2>
    <material>Gazebo/Orange</material>
  </gazebo>
  <gazebo reference="base_laser_link">
    <material>
      Gazebo/Orange
    </material>
  </gazebo>
  <gazebo>
    <plugin filename="libgazebo_kaqi_base_plugin.so" name="base_controller">
      <node_namespace/>
      <update_rate>100</update_rate>
      <publish_odom_tf>false</publish_odom_tf>
      <publish_wheel_tf_>true</publish_wheel_tf_>
      <publish_wheel_joint_state_>true</publish_wheel_joint_state_>
      <left_wheel_joint>left_wheel_joint</left_wheel_joint>
      <right_wheel_joint>right_wheel_joint</right_wheel_joint>
      <caster_rotate_joint>caster_rotate_joint</caster_rotate_joint>
      <caster_wheel_joint>caster_wheel_joint</caster_wheel_joint>
      <wheel_diameter>0.076</wheel_diameter>
      <wheel_separation>0.34</wheel_separation>
      <wheel_torque>20.0</wheel_torque>
      <wheel_acceleration>2.0</wheel_acceleration>
      <command_topic>/base_controller/command</command_topic>
      <odometry_topic>/odom</odometry_topic>
      <odom_frame>odom</odom_frame>
      <base_frame>base_footprint</base_frame>
    </plugin>
  </gazebo>
  <gazebo reference="head_kinect_link">
    <sensor name="head_kinect_sensor" type="depth">
      <always_on>true</always_on>
      <update_rate>20.0</update_rate>
      <camera>
        <horizontal_fov>0.994837673637</horizontal_fov>
        <image>
          <format>B8G8R8</format>
          <width>640</width>
          <height>480</height>
        </image>
        <clip>
          <near>0.05</near>
          <far>10</far>
        </clip>
      </camera>
      <plugin filename="libgazebo_ros_openni_kinect.so" name="head_kinect_controller">
        <alwaysOn>true</alwaysOn>
        <updateRate>20.0</updateRate>
        <robotNamespace>/</robotNamespace>
        <cameraName>head_kinect</cameraName>
        <imageTopicName>/head_kinect/rgb/image_raw</imageTopicName>
        <cameraInfoTopicName>/head_kinect/rgb/camera_info</cameraInfoTopicName>
        <depthImageTopicName>/head_kinect/depth/image_raw</depthImageTopicName>
        <depthImageCameraInfoTopicName>/head_kinect/depth/camera_info</depthImageCameraInfoTopicName>
        <pointCloudTopicName>/head_kinect/depth_registered/points</pointCloudTopicName>
        <frameName>head_kinect_optical_frame</frameName>
        <pointCloudCutoff>0.5</pointCloudCutoff>
        <pointCloudCutoffMax>6.0</pointCloudCutoffMax>
        <distortionK1>0.00000001</distortionK1>
        <distortionK2>0.00000001</distortionK2>
        <distortionK3>0.00000001</distortionK3>
        <distortionT1>0.00000001</distortionT1>
        <distortionT2>0.00000001</distortionT2>
        <CxPrime>0</CxPrime>
        <Cx>0</Cx>
        <Cy>0</Cy>
        <focalLength>0</focalLength>
        <hackBaseline>0</hackBaseline>
      </plugin>
    </sensor>
  </gazebo>
  <gazebo reference="base_laser_frame">
    <sensor name="base_laser_sensor" type="ray">
      <always_on>true</always_on>
      <update_rate>30</update_rate>
      <pose>0 0 0 0 0 0</pose>
      <visualize>false</visualize>
      <ray>
        <scan>
          <horizontal>
            <samples>1080</samples>
            <resolution>1</resolution>
            <min_angle>-2.35619449</min_angle>
            <max_angle>2.35619449</max_angle>
          </horizontal>
        </scan>
        <range>
          <min>0.08</min>
          <max>30.0</max>
          <resolution>0.01</resolution>
        </range>
      </ray>
      <plugin filename="libgazebo_ros_laser.so" name="gazebo_ros_base_laser_controller">
        <robotNamespace>/</robotNamespace>
        <gaussianNoise>0.005</gaussianNoise>
        <alwaysOn>true</alwaysOn>
        <updateRate>30</updateRate>
        <topicName>base_scan</topicName>
        <frameName>base_laser_frame</frameName>
        <hokuyoMinIntensity>101</hokuyoMinIntensity>
      </plugin>
    </sensor>
  </gazebo>
  <!-- 0.016 -->
  <!-- 0.0 -->
  <!-- len: cm -->
  <link name="base_footprint">
    </link>
  <joint name="base_footprint_joint" type="fixed">
    <origin rpy="0 0 0" xyz="0 0 0.068"/>
    <parent link="base_footprint"/>
    <child link="base_link"/>
  </joint>
  <link name="base_link">
    <inertial>
      <origin rpy="0 0 0" xyz="0 0 0"/>
      <mass value="0.59157"/>
      <inertia ixx="0.1" ixy="0" ixz="0" iyy="0.1" iyz="0" izz="0.1"/>
    </inertial>
    <visual>
      <origin rpy="1.57079632679 0 -1.57079632679" xyz="-0.13 0 0"/>
      <geometry>
        <mesh filename="package://kaqi_description/meshes/base_link.stl"/>
      </geometry>
      <material name="">
        <color rgba="1 1 1 0.5"/>
      </material>
    </visual>
    <collision>
      <origin rpy="0 0 0" xyz="-0.13 0 0.0025"/>
      <geometry>
        <box size=".32 .28 .005"/>
      </geometry>
    </collision>
  </link>
  <joint name="left_wheel_joint" type="continuous">
    <origin rpy="0 0 0" xyz="0 0.15923 -0.0359"/>
    <axis xyz="0 1 0"/>
    <parent link="base_link"/>
    <child link="left_wheel_link"/>
    <limit effort="60.5" velocity="100"/>
    <safety_controller k_velocity="10"/>
    <calibration rising="0"/>
    <dynamics damping="1.0" friction="0.0"/>
  </joint>
  <link name="left_wheel_link">
    <inertial>
      <origin rpy="0 0 0" xyz="0 0 0"/>
      <mass value="0.15556"/>
      <inertia ixx="0.001" ixy="0" ixz="0" iyy="0.001" iyz="0" izz="0.001"/>
    </inertial>
    <visual>
      <origin rpy="1.57079632679 0 0" xyz="0 0 0"/>
      <geometry>
        <cylinder length="0.030" radius="0.0321"/>
      </geometry>
      <material name="">
        <color rgba="0.1 0.1 0.1 1"/>
      </material>
    </visual>
    <collision>
      <origin rpy="1.57079632679 0 0" xyz="0 0 0"/>
      <geometry>
        <cylinder length="0.030" radius="0.0321"/>
      </geometry>
    </collision>
  </link>
  <joint name="right_wheel_joint" type="continuous">
    <origin rpy="0 0 0" xyz="0 -0.15923 -0.0359"/>
    <axis xyz="0 1 0"/>
    <parent link="base_link"/>
    <child link="right_wheel_link"/>
    <limit effort="60.5" velocity="100"/>
    <safety_controller k_velocity="10"/>
    <calibration rising="0"/>
    <dynamics damping="1.0" friction="0.0"/>
  </joint>
  <link name="right_wheel_link">
    <inertial>
      <origin rpy="0 0 0" xyz="0 0 0"/>
      <mass value="0.15556"/>
      <inertia ixx="0.001" ixy="0" ixz="0" iyy="0.001" iyz="0" izz="0.001"/>
    </inertial>
    <visual>
      <origin rpy="1.57079632679 0 0" xyz="0 0 0"/>
      <geometry>
        <cylinder length="0.030" radius="0.0321"/>
      </geometry>
      <material name="">
        <color rgba="0.1 0.1 0.1 1"/>
      </material>
    </visual>
    <collision>
      <origin rpy="1.57079632679 0 0" xyz="0 0 0"/>
      <geometry>
        <cylinder length="0.030" radius="0.0321"/>
      </geometry>
    </collision>
  </link>
  <!-- Caster -->
  <joint name="caster_base_joint" type="fixed">
    <origin rpy="0 0 0" xyz="-0.23 0 0.003"/>
    <parent link="base_link"/>
    <child link="caster_base_link"/>
  </joint>
  <link name="caster_base_link">
    <inertial>
      <origin rpy="0 0 0" xyz="0 0 0"/>
      <mass value="0.016939"/>
      <inertia ixx="0.001" ixy="0" ixz="0" iyy="0.001" iyz="0" izz="0.001"/>
    </inertial>
    <visual>
      <origin rpy="1.57079632679 0 0" xyz="0 0 -0.001"/>
      <geometry>
        <mesh filename="package://kaqi_description/meshes/caster_base.stl"/>
      </geometry>
      <material name="">
        <color rgba="1 1 1 1"/>
      </material>
    </visual>
    <collision>
      <origin rpy="0 0 0" xyz="0 0 0.003"/>
      <geometry>
        <box size=".055 .046 .006"/>
      </geometry>
    </collision>
  </link>
  <joint name="caster_rotate_joint" type="continuous">
    <origin rpy="0 0 0" xyz="0.0 0.0 -0.006"/>
    <axis xyz="0 0 1"/>
    <parent link="caster_base_link"/>
    <child link="caster_rotate_link"/>
  </joint>
  <link name="caster_rotate_link">
    <inertial>
      <origin rpy="0 0 0" xyz="0 0 0.015"/>
      <mass value="0.0043659"/>
      <inertia ixx="0.0001" ixy="0" ixz="0" iyy="0.0001" iyz="0" izz="0.0001"/>
    </inertial>
    <visual>
      <origin rpy="-1.57079632679 0 0" xyz="0 0 0"/>
      <geometry>
        <mesh filename="package://kaqi_description/meshes/caster_rotate.stl"/>
      </geometry>
      <material name="">
        <color rgba="0.3 0.3 0.3 1"/>
      </material>
    </visual>
    <!--
    <collision>
      <origin xyz="0 0 0" rpy="${-M_PI/2.0} 0 0" />
      <geometry>
        <mesh filename="package://kaqi_description/meshes/caster_rotate.stl" />
      </geometry>
    </collision>
    -->
  </link>
  <joint name="caster_wheel_joint" type="continuous">
    <origin rpy="0 0 0" xyz="-0.02 0.0 -0.04"/>
    <axis xyz="0 1 0"/>
    <parent link="caster_rotate_link"/>
    <child link="caster_wheel_link"/>
  </joint>
  <link name="caster_wheel_link">
    <inertial>
      <origin rpy="0 0 0" xyz="0 0 0"/>
      <mass value="0.037975"/>
      <inertia ixx="0.001" ixy="0" ixz="0" iyy="0.001" iyz="0" izz="0.001"/>
    </inertial>
    <visual>
      <origin rpy="1.57079632679 0 0" xyz="0 0 0"/>
      <geometry>
        <mesh filename="package://kaqi_description/meshes/caster_wheel.stl"/>
      </geometry>
      <material name="">
        <color rgba="1.0 0.27 0 1"/>
      </material>
    </visual>
    <collision>
      <origin rpy="1.57079632679 0 0" xyz="0 0 0"/>
      <geometry>
        <cylinder length="0.011" radius="0.025"/>
      </geometry>
    </collision>
  </link>
  <!-- Stacks -->
  <joint name="standoff_10_0_joint" type="fixed">
    <origin rpy="0 0 0" xyz="-0.01 -0.08 0.005"/>
    <parent link="base_link"/>
    <child link="standoff_10_0_link"/>
  </joint>
  <link name="standoff_10_0_link">
    <inertial>
      <mass value="0.01"/>
      <origin xyz="0 0 0"/>
      <inertia ixx="0.001" ixy="0.0" ixz="0.0" iyy="0.001" iyz="0.0" izz="0.001"/>
    </inertial>
    <visual>
      <origin rpy="0 0 0" xyz="0 0 0.05"/>
      <geometry>
        <cylinder length="0.1" radius="0.005"/>
      </geometry>
      <material name="">
        <color rgba="1 1 1 1"/>
      </material>
    </visual>
    <collision>
      <origin rpy="0 0 0" xyz="0 0 0.05"/>
      <geometry>
        <cylinder length="0.1" radius="0.005"/>
      </geometry>
    </collision>
  </link>
  <joint name="standoff_10_1_joint" type="fixed">
    <origin rpy="0 0 0" xyz="-0.01 0.08 0.005"/>
    <parent link="base_link"/>
    <child link="standoff_10_1_link"/>
  </joint>
  <link name="standoff_10_1_link">
    <inertial>
      <mass value="0.01"/>
      <origin xyz="0 0 0"/>
      <inertia ixx="0.001" ixy="0.0" ixz="0.0" iyy="0.001" iyz="0.0" izz="0.001"/>
    </inertial>
    <visual>
      <origin rpy="0 0 0" xyz="0 0 0.05"/>
      <geometry>
        <cylinder length="0.1" radius="0.005"/>
      </geometry>
      <material name="">
        <color rgba="1 1 1 1"/>
      </material>
    </visual>
    <collision>
      <origin rpy="0 0 0" xyz="0 0 0.05"/>
      <geometry>
        <cylinder length="0.1" radius="0.005"/>
      </geometry>
    </collision>
  </link>
  <joint name="standoff_10_2_joint" type="fixed">
    <origin rpy="0 0 0" xyz="-0.25 0.08 0.005"/>
    <parent link="base_link"/>
    <child link="standoff_10_2_link"/>
  </joint>
  <link name="standoff_10_2_link">
    <inertial>
      <mass value="0.01"/>
      <origin xyz="0 0 0"/>
      <inertia ixx="0.001" ixy="0.0" ixz="0.0" iyy="0.001" iyz="0.0" izz="0.001"/>
    </inertial>
    <visual>
      <origin rpy="0 0 0" xyz="0 0 0.05"/>
      <geometry>
        <cylinder length="0.1" radius="0.005"/>
      </geometry>
      <material name="">
        <color rgba="1 1 1 1"/>
      </material>
    </visual>
    <collision>
      <origin rpy="0 0 0" xyz="0 0 0.05"/>
      <geometry>
        <cylinder length="0.1" radius="0.005"/>
      </geometry>
    </collision>
  </link>
  <joint name="standoff_10_3_joint" type="fixed">
    <origin rpy="0 0 0" xyz="-0.25 -0.08 0.005"/>
    <parent link="base_link"/>
    <child link="standoff_10_3_link"/>
  </joint>
  <link name="standoff_10_3_link">
    <inertial>
      <mass value="0.01"/>
      <origin xyz="0 0 0"/>
      <inertia ixx="0.001" ixy="0.0" ixz="0.0" iyy="0.001" iyz="0.0" izz="0.001"/>
    </inertial>
    <visual>
      <origin rpy="0 0 0" xyz="0 0 0.05"/>
      <geometry>
        <cylinder length="0.1" radius="0.005"/>
      </geometry>
      <material name="">
        <color rgba="1 1 1 1"/>
      </material>
    </visual>
    <collision>
      <origin rpy="0 0 0" xyz="0 0 0.05"/>
      <geometry>
        <cylinder length="0.1" radius="0.005"/>
      </geometry>
    </collision>
  </link>
  <joint name="plate1_0_joint" type="fixed">
    <origin rpy="0 0 0" xyz="-0.13 0 0.105"/>
    <parent link="base_link"/>
    <child link="plate1_0_link"/>
  </joint>
  <link name="plate1_0_link">
    <inertial>
      <mass value="0.01"/>
      <origin xyz="0 0 0"/>
      <inertia ixx="0.001" ixy="0.0" ixz="0.0" iyy="0.001" iyz="0.0" izz="0.001"/>
    </inertial>
    <visual>
      <origin rpy="1.57079632679 0 -1.57079632679" xyz="0 0 0.0"/>
      <geometry>
        <mesh filename="package://kaqi_description/meshes/plate1.stl"/>
      </geometry>
      <material name="">
        <color rgba="1 1 1 0.5"/>
        <ambient>1 1 1 0.5</ambient>
        <diffuse>1 1 1 0.5</diffuse>
        <specular>0.1 0.1 0.1 128</specular>
        <emissive>0 0 0 0</emissive>
      </material>
    </visual>
    <collision>
      <origin rpy="0 0 0" xyz="0 0 0.0025"/>
      <geometry>
        <box size=".36 .36 .005"/>
      </geometry>
    </collision>
  </link>
  <joint name="standoff_40_0_joint" type="fixed">
    <origin rpy="0 0 0" xyz="-0.12 0.12 0.005"/>
    <parent link="plate1_0_link"/>
    <child link="standoff_40_0_link"/>
  </joint>
  <link name="standoff_40_0_link">
    <inertial>
      <mass value="0.01"/>
      <origin xyz="0 0 0"/>
      <inertia ixx="0.001" ixy="0.0" ixz="0.0" iyy="0.001" iyz="0.0" izz="0.001"/>
    </inertial>
    <visual>
      <origin rpy="0 0 0" xyz="0 0 0.2"/>
      <geometry>
        <cylinder length="0.4" radius="0.005"/>
      </geometry>
      <material name="">
        <color rgba="1 1 1 1"/>
      </material>
    </visual>
    <collision>
      <origin rpy="0 0 0" xyz="0 0 0.2"/>
      <geometry>
        <cylinder length="0.4" radius="0.005"/>
      </geometry>
    </collision>
  </link>
  <joint name="standoff_40_1_joint" type="fixed">
    <origin rpy="0 0 0" xyz="-0.12 -0.12 0.005"/>
    <parent link="plate1_0_link"/>
    <child link="standoff_40_1_link"/>
  </joint>
  <link name="standoff_40_1_link">
    <inertial>
      <mass value="0.01"/>
      <origin xyz="0 0 0"/>
      <inertia ixx="0.001" ixy="0.0" ixz="0.0" iyy="0.001" iyz="0.0" izz="0.001"/>
    </inertial>
    <visual>
      <origin rpy="0 0 0" xyz="0 0 0.2"/>
      <geometry>
        <cylinder length="0.4" radius="0.005"/>
      </geometry>
      <material name="">
        <color rgba="1 1 1 1"/>
      </material>
    </visual>
    <collision>
      <origin rpy="0 0 0" xyz="0 0 0.2"/>
      <geometry>
        <cylinder length="0.4" radius="0.005"/>
      </geometry>
    </collision>
  </link>
  <joint name="standoff_40_2_joint" type="fixed">
    <origin rpy="0 0 0" xyz="0.12 0.12 0.005"/>
    <parent link="plate1_0_link"/>
    <child link="standoff_40_2_link"/>
  </joint>
  <link name="standoff_40_2_link">
    <inertial>
      <mass value="0.01"/>
      <origin xyz="0 0 0"/>
      <inertia ixx="0.001" ixy="0.0" ixz="0.0" iyy="0.001" iyz="0.0" izz="0.001"/>
    </inertial>
    <visual>
      <origin rpy="0 0 0" xyz="0 0 0.2"/>
      <geometry>
        <cylinder length="0.4" radius="0.005"/>
      </geometry>
      <material name="">
        <color rgba="1 1 1 1"/>
      </material>
    </visual>
    <collision>
      <origin rpy="0 0 0" xyz="0 0 0.2"/>
      <geometry>
        <cylinder length="0.4" radius="0.005"/>
      </geometry>
    </collision>
  </link>
  <joint name="standoff_40_3_joint" type="fixed">
    <origin rpy="0 0 0" xyz="0.12 -0.12 0.005"/>
    <parent link="plate1_0_link"/>
    <child link="standoff_40_3_link"/>
  </joint>
  <link name="standoff_40_3_link">
    <inertial>
      <mass value="0.01"/>
      <origin xyz="0 0 0"/>
      <inertia ixx="0.001" ixy="0.0" ixz="0.0" iyy="0.001" iyz="0.0" izz="0.001"/>
    </inertial>
    <visual>
      <origin rpy="0 0 0" xyz="0 0 0.2"/>
      <geometry>
        <cylinder length="0.4" radius="0.005"/>
      </geometry>
      <material name="">
        <color rgba="1 1 1 1"/>
      </material>
    </visual>
    <collision>
      <origin rpy="0 0 0" xyz="0 0 0.2"/>
      <geometry>
        <cylinder length="0.4" radius="0.005"/>
      </geometry>
    </collision>
  </link>
  <joint name="plate1_1_joint" type="fixed">
    <origin rpy="0 0 0" xyz="0 0 0.405"/>
    <parent link="plate1_0_link"/>
    <child link="plate1_1_link"/>
  </joint>
  <link name="plate1_1_link">
    <inertial>
      <mass value="0.01"/>
      <origin xyz="0 0 0"/>
      <inertia ixx="0.001" ixy="0.0" ixz="0.0" iyy="0.001" iyz="0.0" izz="0.001"/>
    </inertial>
    <visual>
      <origin rpy="1.57079632679 0 -1.57079632679" xyz="0 0 0.0"/>
      <geometry>
        <mesh filename="package://kaqi_description/meshes/plate1.stl"/>
      </geometry>
      <material name="">
        <color rgba="1 1 1 0.5"/>
        <ambient>1 1 1 0.5</ambient>
        <diffuse>1 1 1 0.5</diffuse>
        <specular>0.1 0.1 0.1 128</specular>
        <emissive>0 0 0 0</emissive>
      </material>
    </visual>
    <collision>
      <origin rpy="0 0 0" xyz="0 0 0.0025"/>
      <geometry>
        <box size=".36 .36 .005"/>
      </geometry>
    </collision>
  </link>
  <joint name="standoff_kinect_0_joint" type="fixed">
    <origin rpy="0 0 0" xyz="0 0.098 0.005"/>
    <parent link="plate1_1_link"/>
    <child link="standoff_kinect_0_link"/>
  </joint>
  <link name="standoff_kinect_0_link">
    <inertial>
      <mass value="0.001"/>
      <origin xyz="0 0 0"/>
      <inertia ixx="0.0001" ixy="0.0" ixz="0.0" iyy="0.0001" iyz="0.0" izz="0.0001"/>
    </inertial>
    <visual>
      <origin rpy="0 0 0" xyz="0 0 0.056"/>
      <geometry>
        <cylinder length="0.112" radius="0.005"/>
      </geometry>
      <material name="">
        <color rgba="1 1 1 1"/>
      </material>
    </visual>
    <collision>
      <origin rpy="0 0 0" xyz="0 0 0.056"/>
      <geometry>
        <cylinder length="0.112" radius="0.005"/>
      </geometry>
    </collision>
  </link>
  <joint name="standoff_kinect_1_joint" type="fixed">
    <origin rpy="0 0 0" xyz="0 -0.098 0.005"/>
    <parent link="plate1_1_link"/>
    <child link="standoff_kinect_1_link"/>
  </joint>
  <link name="standoff_kinect_1_link">
    <inertial>
      <mass value="0.001"/>
      <origin xyz="0 0 0"/>
      <inertia ixx="0.0001" ixy="0.0" ixz="0.0" iyy="0.0001" iyz="0.0" izz="0.0001"/>
    </inertial>
    <visual>
      <origin rpy="0 0 0" xyz="0 0 0.056"/>
      <geometry>
        <cylinder length="0.112" radius="0.005"/>
      </geometry>
      <material name="">
        <color rgba="1 1 1 1"/>
      </material>
    </visual>
    <collision>
      <origin rpy="0 0 0" xyz="0 0 0.056"/>
      <geometry>
        <cylinder length="0.112" radius="0.005"/>
      </geometry>
    </collision>
  </link>
  <!-- Sensors -->
  <!-- Gyro -->
  <joint name="gyro_joint" type="fixed">
    <axis xyz="0 1 0"/>
    <origin rpy="0 0 0" xyz="0 0 0.02"/>
    <parent link="base_link"/>
    <child link="gyro_link"/>
  </joint>
  <link name="gyro_link">
    <inertial>
      <mass value="0.001"/>
      <origin rpy="0 0 0" xyz="0 0 0"/>
      <inertia ixx="0.0001" ixy="0" ixz="0" iyy="0.000001" iyz="0" izz="0.0001"/>
    </inertial>
  </link>
  <!-- IMU -->
  <joint name="imu_joint" type="fixed">
    <axis xyz="0 1 0"/>
    <origin rpy="0 3.14159265359 0" xyz="0 0 0.07"/>
    <parent link="base_link"/>
    <child link="imu_link"/>
  </joint>
  <link name="imu_link">
    <inertial>
      <mass value="0.001"/>
      <origin rpy="0 0 0" xyz="0 0 0"/>
      <inertia ixx="0.0001" ixy="0" ixz="0" iyy="0.000001" iyz="0" izz="0.0001"/>
    </inertial>
  </link>
  <!-- kinect -->
  <joint name="head_kinect_joint" type="fixed">
    <origin rpy="0 0 0" xyz="-0.014 0.036 0.136"/>
    <parent link="plate1_1_link"/>
    <child link="head_kinect_link"/>
  </joint>
  <link name="head_kinect_link">
    <inertial>
      <mass value="0.1"/>
      <origin xyz="0 0 0"/>
      <inertia ixx="0.01" ixy="0" ixz="0" iyy="0.01" iyz="0" izz="0.01"/>
    </inertial>
    <visual>
      <origin rpy="0 0 0" xyz="0.034 -0.036 0"/>
      <geometry>
        <mesh filename="package://kaqi_description/meshes/kinect.dae" scale="0.001 0.001 0.001"/>
      </geometry>
    </visual>
    <!--
      <collision>
        <origin xyz="${-cam_px+0.02} ${-cam_py} 0" rpy="0 0 0" />
        <geometry>
          <mesh filename="package://kaqi_description/meshes/kinect.dae" scale="0.001 0.001 0.001"/>
        </geometry>
      </collision>
    -->
  </link>
  <joint name="head_kinect_optical_joint" type="fixed">
    <origin rpy="0 0 0" xyz="-0.03 0 0"/>
    <parent link="head_kinect_link"/>
    <child link="head_kinect_optical_link"/>
  </joint>
  <link name="head_kinect_optical_link">
    <inertial>
      <mass value="0.1"/>
      <origin rpy="0 0 0" xyz="0 0 0"/>
      <inertia ixx="0.01" ixy="0.0" ixz="0.0" iyy="0.01" iyz="0.0" izz="0.01"/>
    </inertial>
    <visual>
      <origin rpy="0 0 0" xyz="0.0 0.0 0"/>
      <geometry>
        <sphere radius="0.0005"/>
      </geometry>
    </visual>
  </link>
  <joint name="head_kinect_optical_frame_joint" type="fixed">
    <origin rpy="-1.57079632679 0 -1.57079632679" xyz="0 0 0"/>
    <parent link="head_kinect_optical_link"/>
    <child link="head_kinect_optical_frame"/>
  </joint>
  <link name="head_kinect_optical_frame"/>
  <!-- UTM30LX laser range finder -->
  <!--
    <joint name="base_laser_joint" type="fixed">
      <origin xyz="${laser_px} ${laser_py} ${laser_pz}" rpy="${laser_ox} ${laser_oy} ${laser_oz}" />
      <parent link="base_link"/>
      <child link="base_laser_link" />
    </joint>

    <link name="base_laser_link">
      <inertial>
        <mass value="0.1" />
        <origin xyz="0 0 0" />
        <inertia  ixx="0.01" ixy="0" ixz="0"
                  iyy="0.01" iyz="0" izz="0.01" />
      </inertial>
      <visual>
        <origin xyz="0 0 0" rpy="${M_PI/2.0} 0 ${M_PI/2.0}"/>
        <geometry>
          <mesh filename="package://kaqi_description/meshes/hokuyo_utm30lx.stl" scale="0.001 0.001 0.001"/>
        </geometry>
        <material name="hokuyo_color">
          <color rgba="0.4 0.2 0.2 1.0"/>
        </material>
      </visual>
      <collision>
        <origin xyz="0 0 0.0435" rpy="0 0 0" />
        <geometry>
          <box size=".06 .06 .087"/>
        </geometry>
      </collision>
    </link>

    <joint name="base_laser_frame_joint" type="fixed">
      <origin xyz="0 0 0.055" rpy="0 0 0" />
      <parent link="base_laser_link"/>
      <child link="base_laser_frame" />
    </joint>

    <link name="base_laser_frame">
      <inertial>
        <mass value="0.1" />
        <origin xyz="0 0 0" />
        <inertia  ixx="0.01" ixy="0" ixz="0"
                  iyy="0.01" iyz="0" izz="0.01" />
      </inertial>
    </link>

-->
</robot>

